pa_autoconfigure_django.pyスクリプトの実行中にエラーが表示された場合は、次のような原因が考えられます。

-PythonAnywhere APIトークンの作成を忘れている
-あなたのGitHubのURLを間違えている
-Could not find your settings.pyというエラーが表示された場合は、おそらくGitにすべてのファイルを追加できていなかったか、 GitHubにうまくプッシュできていなかった。 この場合はGitセクションをもう一度見てください
-PythonAnywhereのアカウントを以前に作成していてcollectstaticでエラーが起きたとしたら、あなたのアカウントで古いバージョンのSQLite（例えば、3.8.2）を使っている可能性があります。 その場合、新しいアカウントを作成して、上記のPythonAnywhereのセクションに記載しているコマンドを実行してください。

サイトにアクセスしようとするとエラーが表示された場合、最初にデバッグ情報を探す場所はエラーログです。 PythonAnywhereの Webページには、エラーログへのリンクがあります。 そこにエラーメッセージがあるかどうかを確認してください。 最新のものは一番下にあります。

PythonAnywhereヘルプサイトの一般的なデバッグのヒントもあります。
https://help.pythonanywhere.com/pages/DebuggingImportError
つまづいた時は、コーチに助けを求めましょう。